2024-07-23 02:49:42,292 - ERROR - Error executing python3 manage.py sync_gcp_cost_resource 2024-01-01 10: Command 'python3 manage.py sync_gcp_cost_resource 2024-01-01 10' died with <Signals.SIGINT: 2>.
Traceback (most recent call last):
  File "/Users/pimenvibritania/Moladin/cost-management-system/manage.py", line 22, in <module>
    main()
  File "/Users/pimenvibritania/Moladin/cost-management-system/manage.py", line 18, in main
    execute_from_command_line(sys.argv)
  File "/Users/pimenvibritania/Moladin/cost-management-system/.venv/lib/python3.11/site-packages/django/core/management/__init__.py", line 442, in execute_from_command_line
    utility.execute()
  File "/Users/pimenvibritania/Moladin/cost-management-system/.venv/lib/python3.11/site-packages/django/core/management/__init__.py", line 436, in execute
    self.fetch_command(subcommand).run_from_argv(self.argv)
  File "/Users/pimenvibritania/Moladin/cost-management-system/.venv/lib/python3.11/site-packages/django/core/management/base.py", line 412, in run_from_argv
    self.execute(*args, **cmd_options)
  File "/Users/pimenvibritania/Moladin/cost-management-system/.venv/lib/python3.11/site-packages/django/core/management/base.py", line 458, in execute
    output = self.handle(*args, **options)
             ^^^^^^^^^^^^^^^^^^^^^^^^^^^^^
  File "/Users/pimenvibritania/Moladin/cost-management-system/core/management/commands/sync_gcp_cost_resource.py", line 25, in handle
    GCPCostResource.sync_cost(current_date_f)
  File "/Users/pimenvibritania/Moladin/cost-management-system/api/models/v2/gcp_cost_resource.py", line 201, in sync_cost
    "conversion_rate": BQ.get_daily_conversion_rate(usage_date),
                       ^^^^^^^^^^^^^^^^^^^^^^^^^^^^^^^^^^^^^^^^
  File "/Users/pimenvibritania/Moladin/cost-management-system/api/models/bigquery.py", line 59, in get_daily_conversion_rate
    query_job = cls().client.query(query)
                ^^^^^^^^^^^^^^^^^^^^^^^^^
  File "/Users/pimenvibritania/Moladin/cost-management-system/.venv/lib/python3.11/site-packages/google/cloud/bigquery/client.py", line 3483, in query
    return _job_helpers.query_jobs_insert(
           ^^^^^^^^^^^^^^^^^^^^^^^^^^^^^^^
  File "/Users/pimenvibritania/Moladin/cost-management-system/.venv/lib/python3.11/site-packages/google/cloud/bigquery/_job_helpers.py", line 158, in query_jobs_insert
    future = do_query()
             ^^^^^^^^^^
  File "/Users/pimenvibritania/Moladin/cost-management-system/.venv/lib/python3.11/site-packages/google/cloud/bigquery/_job_helpers.py", line 135, in do_query
    query_job._begin(retry=retry, timeout=timeout)
  File "/Users/pimenvibritania/Moladin/cost-management-system/.venv/lib/python3.11/site-packages/google/cloud/bigquery/job/query.py", line 1374, in _begin
    super(QueryJob, self)._begin(client=client, retry=retry, timeout=timeout)
  File "/Users/pimenvibritania/Moladin/cost-management-system/.venv/lib/python3.11/site-packages/google/cloud/bigquery/job/base.py", line 740, in _begin
    api_response = client._call_api(
                   ^^^^^^^^^^^^^^^^^
  File "/Users/pimenvibritania/Moladin/cost-management-system/.venv/lib/python3.11/site-packages/google/cloud/bigquery/client.py", line 831, in _call_api
    return call()
           ^^^^^^
  File "/Users/pimenvibritania/Moladin/cost-management-system/.venv/lib/python3.11/site-packages/google/api_core/retry/retry_unary.py", line 293, in retry_wrapped_func
    return retry_target(
           ^^^^^^^^^^^^^
  File "/Users/pimenvibritania/Moladin/cost-management-system/.venv/lib/python3.11/site-packages/google/api_core/retry/retry_unary.py", line 144, in retry_target
    result = target()
             ^^^^^^^^
  File "/Users/pimenvibritania/Moladin/cost-management-system/.venv/lib/python3.11/site-packages/google/cloud/_http/__init__.py", line 482, in api_request
    response = self._make_request(
               ^^^^^^^^^^^^^^^^^^^
  File "/Users/pimenvibritania/Moladin/cost-management-system/.venv/lib/python3.11/site-packages/google/cloud/_http/__init__.py", line 341, in _make_request
    return self._do_request(
           ^^^^^^^^^^^^^^^^^
  File "/Users/pimenvibritania/Moladin/cost-management-system/.venv/lib/python3.11/site-packages/google/cloud/_http/__init__.py", line 379, in _do_request
    return self.http.request(
           ^^^^^^^^^^^^^^^^^^
  File "/Users/pimenvibritania/Moladin/cost-management-system/.venv/lib/python3.11/site-packages/google/auth/transport/requests.py", line 541, in request
    response = super(AuthorizedSession, self).request(
               ^^^^^^^^^^^^^^^^^^^^^^^^^^^^^^^^^^^^^^^
  File "/Users/pimenvibritania/Moladin/cost-management-system/.venv/lib/python3.11/site-packages/requests/sessions.py", line 589, in request
    resp = self.send(prep, **send_kwargs)
           ^^^^^^^^^^^^^^^^^^^^^^^^^^^^^^
  File "/Users/pimenvibritania/Moladin/cost-management-system/.venv/lib/python3.11/site-packages/requests/sessions.py", line 703, in send
    r = adapter.send(request, **kwargs)
        ^^^^^^^^^^^^^^^^^^^^^^^^^^^^^^^
  File "/Users/pimenvibritania/Moladin/cost-management-system/.venv/lib/python3.11/site-packages/requests/adapters.py", line 486, in send
    resp = conn.urlopen(
           ^^^^^^^^^^^^^
  File "/Users/pimenvibritania/Moladin/cost-management-system/.venv/lib/python3.11/site-packages/urllib3/connectionpool.py", line 793, in urlopen
    response = self._make_request(
               ^^^^^^^^^^^^^^^^^^^
  File "/Users/pimenvibritania/Moladin/cost-management-system/.venv/lib/python3.11/site-packages/urllib3/connectionpool.py", line 467, in _make_request
    self._validate_conn(conn)
  File "/Users/pimenvibritania/Moladin/cost-management-system/.venv/lib/python3.11/site-packages/urllib3/connectionpool.py", line 1099, in _validate_conn
    conn.connect()
  File "/Users/pimenvibritania/Moladin/cost-management-system/.venv/lib/python3.11/site-packages/urllib3/connection.py", line 653, in connect
    sock_and_verified = _ssl_wrap_socket_and_match_hostname(
                        ^^^^^^^^^^^^^^^^^^^^^^^^^^^^^^^^^^^^
  File "/Users/pimenvibritania/Moladin/cost-management-system/.venv/lib/python3.11/site-packages/urllib3/connection.py", line 806, in _ssl_wrap_socket_and_match_hostname
    ssl_sock = ssl_wrap_socket(
               ^^^^^^^^^^^^^^^^
  File "/Users/pimenvibritania/Moladin/cost-management-system/.venv/lib/python3.11/site-packages/urllib3/util/ssl_.py", line 465, in ssl_wrap_socket
    ssl_sock = _ssl_wrap_socket_impl(sock, context, tls_in_tls, server_hostname)
               ^^^^^^^^^^^^^^^^^^^^^^^^^^^^^^^^^^^^^^^^^^^^^^^^^^^^^^^^^^^^^^^^^
  File "/Users/pimenvibritania/Moladin/cost-management-system/.venv/lib/python3.11/site-packages/urllib3/util/ssl_.py", line 509, in _ssl_wrap_socket_impl
    return ssl_context.wrap_socket(sock, server_hostname=server_hostname)
           ^^^^^^^^^^^^^^^^^^^^^^^^^^^^^^^^^^^^^^^^^^^^^^^^^^^^^^^^^^^^^^
  File "/Library/Frameworks/Python.framework/Versions/3.11/lib/python3.11/ssl.py", line 517, in wrap_socket
    return self.sslsocket_class._create(
           ^^^^^^^^^^^^^^^^^^^^^^^^^^^^^
  File "/Library/Frameworks/Python.framework/Versions/3.11/lib/python3.11/ssl.py", line 1108, in _create
    self.do_handshake()
  File "/Library/Frameworks/Python.framework/Versions/3.11/lib/python3.11/ssl.py", line 1379, in do_handshake
    self._sslobj.do_handshake()
KeyboardInterrupt

2024-07-23 02:49:42,294 - ERROR - Error executing python3 manage.py sync_gcp_cost_resource 2024-01-11 10: Command 'python3 manage.py sync_gcp_cost_resource 2024-01-11 10' died with <Signals.SIGINT: 2>.
Traceback (most recent call last):
  File "/Users/pimenvibritania/Moladin/cost-management-system/.venv/lib/python3.11/site-packages/django/db/backends/utils.py", line 89, in _execute
    return self.cursor.execute(sql, params)
           ^^^^^^^^^^^^^^^^^^^^^^^^^^^^^^^^
  File "/Users/pimenvibritania/Moladin/cost-management-system/.venv/lib/python3.11/site-packages/django/db/backends/mysql/base.py", line 75, in execute
    return self.cursor.execute(query, args)
           ^^^^^^^^^^^^^^^^^^^^^^^^^^^^^^^^
  File "/Users/pimenvibritania/Moladin/cost-management-system/.venv/lib/python3.11/site-packages/MySQLdb/cursors.py", line 179, in execute
    res = self._query(mogrified_query)
          ^^^^^^^^^^^^^^^^^^^^^^^^^^^^
  File "/Users/pimenvibritania/Moladin/cost-management-system/.venv/lib/python3.11/site-packages/MySQLdb/cursors.py", line 330, in _query
    db.query(q)
  File "/Users/pimenvibritania/Moladin/cost-management-system/.venv/lib/python3.11/site-packages/MySQLdb/connections.py", line 261, in query
    _mysql.connection.query(self, query)
MySQLdb.IntegrityError: (1062, "Duplicate entry '2024-01-11-6F81-5844-456A_//compute.googleapis.com/projects/4455' for key 'gcp_cost_resources.unique_cost_resource_daily_usage'")

The above exception was the direct cause of the following exception:

Traceback (most recent call last):
  File "/Users/pimenvibritania/Moladin/cost-management-system/api/models/v2/gcp_cost_resource.py", line 226, in sync_cost
    serializer_cost.save()
  File "/Users/pimenvibritania/Moladin/cost-management-system/.venv/lib/python3.11/site-packages/rest_framework/serializers.py", line 212, in save
    self.instance = self.create(validated_data)
                    ^^^^^^^^^^^^^^^^^^^^^^^^^^^
  File "/Users/pimenvibritania/Moladin/cost-management-system/.venv/lib/python3.11/site-packages/rest_framework/serializers.py", line 962, in create
    instance = ModelClass._default_manager.create(**validated_data)
               ^^^^^^^^^^^^^^^^^^^^^^^^^^^^^^^^^^^^^^^^^^^^^^^^^^^^
  File "/Users/pimenvibritania/Moladin/cost-management-system/.venv/lib/python3.11/site-packages/django/db/models/manager.py", line 87, in manager_method
    return getattr(self.get_queryset(), name)(*args, **kwargs)
           ^^^^^^^^^^^^^^^^^^^^^^^^^^^^^^^^^^^^^^^^^^^^^^^^^^^
  File "/Users/pimenvibritania/Moladin/cost-management-system/.venv/lib/python3.11/site-packages/django/db/models/query.py", line 658, in create
    obj.save(force_insert=True, using=self.db)
  File "/Users/pimenvibritania/Moladin/cost-management-system/.venv/lib/python3.11/site-packages/django/db/models/base.py", line 814, in save
    self.save_base(
  File "/Users/pimenvibritania/Moladin/cost-management-system/.venv/lib/python3.11/site-packages/django/db/models/base.py", line 877, in save_base
    updated = self._save_table(
              ^^^^^^^^^^^^^^^^^
  File "/Users/pimenvibritania/Moladin/cost-management-system/.venv/lib/python3.11/site-packages/django/db/models/base.py", line 1020, in _save_table
    results = self._do_insert(
              ^^^^^^^^^^^^^^^^
  File "/Users/pimenvibritania/Moladin/cost-management-system/.venv/lib/python3.11/site-packages/django/db/models/base.py", line 1061, in _do_insert
    return manager._insert(
           ^^^^^^^^^^^^^^^^
  File "/Users/pimenvibritania/Moladin/cost-management-system/.venv/lib/python3.11/site-packages/django/db/models/manager.py", line 87, in manager_method
    return getattr(self.get_queryset(), name)(*args, **kwargs)
           ^^^^^^^^^^^^^^^^^^^^^^^^^^^^^^^^^^^^^^^^^^^^^^^^^^^
  File "/Users/pimenvibritania/Moladin/cost-management-system/.venv/lib/python3.11/site-packages/django/db/models/query.py", line 1805, in _insert
    return query.get_compiler(using=using).execute_sql(returning_fields)
           ^^^^^^^^^^^^^^^^^^^^^^^^^^^^^^^^^^^^^^^^^^^^^^^^^^^^^^^^^^^^^
  File "/Users/pimenvibritania/Moladin/cost-management-system/.venv/lib/python3.11/site-packages/django/db/models/sql/compiler.py", line 1822, in execute_sql
    cursor.execute(sql, params)
  File "/Users/pimenvibritania/Moladin/cost-management-system/.venv/lib/python3.11/site-packages/django/db/backends/utils.py", line 102, in execute
    return super().execute(sql, params)
           ^^^^^^^^^^^^^^^^^^^^^^^^^^^^
  File "/Users/pimenvibritania/Moladin/cost-management-system/.venv/lib/python3.11/site-packages/django/db/backends/utils.py", line 67, in execute
    return self._execute_with_wrappers(
           ^^^^^^^^^^^^^^^^^^^^^^^^^^^^
  File "/Users/pimenvibritania/Moladin/cost-management-system/.venv/lib/python3.11/site-packages/django/db/backends/utils.py", line 80, in _execute_with_wrappers
    return executor(sql, params, many, context)
           ^^^^^^^^^^^^^^^^^^^^^^^^^^^^^^^^^^^^
  File "/Users/pimenvibritania/Moladin/cost-management-system/.venv/lib/python3.11/site-packages/django/db/backends/utils.py", line 84, in _execute
    with self.db.wrap_database_errors:
  File "/Users/pimenvibritania/Moladin/cost-management-system/.venv/lib/python3.11/site-packages/django/db/utils.py", line 91, in __exit__
    raise dj_exc_value.with_traceback(traceback) from exc_value
  File "/Users/pimenvibritania/Moladin/cost-management-system/.venv/lib/python3.11/site-packages/django/db/backends/utils.py", line 89, in _execute
    return self.cursor.execute(sql, params)
           ^^^^^^^^^^^^^^^^^^^^^^^^^^^^^^^^
  File "/Users/pimenvibritania/Moladin/cost-management-system/.venv/lib/python3.11/site-packages/django/db/backends/mysql/base.py", line 75, in execute
    return self.cursor.execute(query, args)
           ^^^^^^^^^^^^^^^^^^^^^^^^^^^^^^^^
  File "/Users/pimenvibritania/Moladin/cost-management-system/.venv/lib/python3.11/site-packages/MySQLdb/cursors.py", line 179, in execute
    res = self._query(mogrified_query)
          ^^^^^^^^^^^^^^^^^^^^^^^^^^^^
  File "/Users/pimenvibritania/Moladin/cost-management-system/.venv/lib/python3.11/site-packages/MySQLdb/cursors.py", line 330, in _query
    db.query(q)
  File "/Users/pimenvibritania/Moladin/cost-management-system/.venv/lib/python3.11/site-packages/MySQLdb/connections.py", line 261, in query
    _mysql.connection.query(self, query)
django.db.utils.IntegrityError: (1062, "Duplicate entry '2024-01-11-6F81-5844-456A_//compute.googleapis.com/projects/4455' for key 'gcp_cost_resources.unique_cost_resource_daily_usage'")

During handling of the above exception, another exception occurred:

Traceback (most recent call last):
  File "/Users/pimenvibritania/Moladin/cost-management-system/manage.py", line 22, in <module>
    main()
  File "/Users/pimenvibritania/Moladin/cost-management-system/manage.py", line 18, in main
    execute_from_command_line(sys.argv)
  File "/Users/pimenvibritania/Moladin/cost-management-system/.venv/lib/python3.11/site-packages/django/core/management/__init__.py", line 442, in execute_from_command_line
    utility.execute()
  File "/Users/pimenvibritania/Moladin/cost-management-system/.venv/lib/python3.11/site-packages/django/core/management/__init__.py", line 436, in execute
    self.fetch_command(subcommand).run_from_argv(self.argv)
  File "/Users/pimenvibritania/Moladin/cost-management-system/.venv/lib/python3.11/site-packages/django/core/management/base.py", line 412, in run_from_argv
    self.execute(*args, **cmd_options)
  File "/Users/pimenvibritania/Moladin/cost-management-system/.venv/lib/python3.11/site-packages/django/core/management/base.py", line 458, in execute
    output = self.handle(*args, **options)
             ^^^^^^^^^^^^^^^^^^^^^^^^^^^^^
  File "/Users/pimenvibritania/Moladin/cost-management-system/core/management/commands/sync_gcp_cost_resource.py", line 25, in handle
    GCPCostResource.sync_cost(current_date_f)
  File "/Users/pimenvibritania/Moladin/cost-management-system/api/models/v2/gcp_cost_resource.py", line 234, in sync_cost
    Notification.send_slack_failed(payload)
  File "/Users/pimenvibritania/Moladin/cost-management-system/api/utils/v2/notify.py", line 62, in send_slack_failed
    res_slack = requests.post(
                ^^^^^^^^^^^^^^
  File "/Users/pimenvibritania/Moladin/cost-management-system/.venv/lib/python3.11/site-packages/requests/api.py", line 115, in post
    return request("post", url, data=data, json=json, **kwargs)
           ^^^^^^^^^^^^^^^^^^^^^^^^^^^^^^^^^^^^^^^^^^^^^^^^^^^^
  File "/Users/pimenvibritania/Moladin/cost-management-system/.venv/lib/python3.11/site-packages/requests/api.py", line 59, in request
    return session.request(method=method, url=url, **kwargs)
           ^^^^^^^^^^^^^^^^^^^^^^^^^^^^^^^^^^^^^^^^^^^^^^^^^
  File "/Users/pimenvibritania/Moladin/cost-management-system/.venv/lib/python3.11/site-packages/requests/sessions.py", line 589, in request
    resp = self.send(prep, **send_kwargs)
           ^^^^^^^^^^^^^^^^^^^^^^^^^^^^^^
  File "/Users/pimenvibritania/Moladin/cost-management-system/.venv/lib/python3.11/site-packages/requests/sessions.py", line 703, in send
    r = adapter.send(request, **kwargs)
        ^^^^^^^^^^^^^^^^^^^^^^^^^^^^^^^
  File "/Users/pimenvibritania/Moladin/cost-management-system/.venv/lib/python3.11/site-packages/requests/adapters.py", line 486, in send
    resp = conn.urlopen(
           ^^^^^^^^^^^^^
  File "/Users/pimenvibritania/Moladin/cost-management-system/.venv/lib/python3.11/site-packages/urllib3/connectionpool.py", line 793, in urlopen
    response = self._make_request(
               ^^^^^^^^^^^^^^^^^^^
  File "/Users/pimenvibritania/Moladin/cost-management-system/.venv/lib/python3.11/site-packages/urllib3/connectionpool.py", line 537, in _make_request
    response = conn.getresponse()
               ^^^^^^^^^^^^^^^^^^
  File "/Users/pimenvibritania/Moladin/cost-management-system/.venv/lib/python3.11/site-packages/urllib3/connection.py", line 466, in getresponse
    httplib_response = super().getresponse()
                       ^^^^^^^^^^^^^^^^^^^^^
  File "/Library/Frameworks/Python.framework/Versions/3.11/lib/python3.11/http/client.py", line 1378, in getresponse
    response.begin()
  File "/Library/Frameworks/Python.framework/Versions/3.11/lib/python3.11/http/client.py", line 318, in begin
    version, status, reason = self._read_status()
                              ^^^^^^^^^^^^^^^^^^^
  File "/Library/Frameworks/Python.framework/Versions/3.11/lib/python3.11/http/client.py", line 279, in _read_status
    line = str(self.fp.readline(_MAXLINE + 1), "iso-8859-1")
               ^^^^^^^^^^^^^^^^^^^^^^^^^^^^^^
  File "/Library/Frameworks/Python.framework/Versions/3.11/lib/python3.11/socket.py", line 706, in readinto
    return self._sock.recv_into(b)
           ^^^^^^^^^^^^^^^^^^^^^^^
  File "/Library/Frameworks/Python.framework/Versions/3.11/lib/python3.11/ssl.py", line 1311, in recv_into
    return self.read(nbytes, buffer)
           ^^^^^^^^^^^^^^^^^^^^^^^^^
  File "/Library/Frameworks/Python.framework/Versions/3.11/lib/python3.11/ssl.py", line 1167, in read
    return self._sslobj.read(len, buffer)
           ^^^^^^^^^^^^^^^^^^^^^^^^^^^^^^
KeyboardInterrupt

2024-07-23 02:49:42,296 - ERROR - Error executing python3 manage.py sync_gcp_cost_resource 2024-01-31 10: Command 'python3 manage.py sync_gcp_cost_resource 2024-01-31 10' died with <Signals.SIGINT: 2>.
Traceback (most recent call last):
  File "/Users/pimenvibritania/Moladin/cost-management-system/.venv/lib/python3.11/site-packages/django/db/backends/utils.py", line 89, in _execute
    return self.cursor.execute(sql, params)
           ^^^^^^^^^^^^^^^^^^^^^^^^^^^^^^^^
  File "/Users/pimenvibritania/Moladin/cost-management-system/.venv/lib/python3.11/site-packages/django/db/backends/mysql/base.py", line 75, in execute
    return self.cursor.execute(query, args)
           ^^^^^^^^^^^^^^^^^^^^^^^^^^^^^^^^
  File "/Users/pimenvibritania/Moladin/cost-management-system/.venv/lib/python3.11/site-packages/MySQLdb/cursors.py", line 179, in execute
    res = self._query(mogrified_query)
          ^^^^^^^^^^^^^^^^^^^^^^^^^^^^
  File "/Users/pimenvibritania/Moladin/cost-management-system/.venv/lib/python3.11/site-packages/MySQLdb/cursors.py", line 330, in _query
    db.query(q)
  File "/Users/pimenvibritania/Moladin/cost-management-system/.venv/lib/python3.11/site-packages/MySQLdb/connections.py", line 261, in query
    _mysql.connection.query(self, query)
MySQLdb.IntegrityError: (1062, "Duplicate entry '2024-01-31-2062-016F-44A2_//compute.googleapis.com/projects/8379' for key 'gcp_cost_resources.unique_cost_resource_daily_usage'")

The above exception was the direct cause of the following exception:

Traceback (most recent call last):
  File "/Users/pimenvibritania/Moladin/cost-management-system/api/models/v2/gcp_cost_resource.py", line 226, in sync_cost
    serializer_cost.save()
  File "/Users/pimenvibritania/Moladin/cost-management-system/.venv/lib/python3.11/site-packages/rest_framework/serializers.py", line 212, in save
    self.instance = self.create(validated_data)
                    ^^^^^^^^^^^^^^^^^^^^^^^^^^^
  File "/Users/pimenvibritania/Moladin/cost-management-system/.venv/lib/python3.11/site-packages/rest_framework/serializers.py", line 962, in create
    instance = ModelClass._default_manager.create(**validated_data)
               ^^^^^^^^^^^^^^^^^^^^^^^^^^^^^^^^^^^^^^^^^^^^^^^^^^^^
  File "/Users/pimenvibritania/Moladin/cost-management-system/.venv/lib/python3.11/site-packages/django/db/models/manager.py", line 87, in manager_method
    return getattr(self.get_queryset(), name)(*args, **kwargs)
           ^^^^^^^^^^^^^^^^^^^^^^^^^^^^^^^^^^^^^^^^^^^^^^^^^^^
  File "/Users/pimenvibritania/Moladin/cost-management-system/.venv/lib/python3.11/site-packages/django/db/models/query.py", line 658, in create
    obj.save(force_insert=True, using=self.db)
  File "/Users/pimenvibritania/Moladin/cost-management-system/.venv/lib/python3.11/site-packages/django/db/models/base.py", line 814, in save
    self.save_base(
  File "/Users/pimenvibritania/Moladin/cost-management-system/.venv/lib/python3.11/site-packages/django/db/models/base.py", line 877, in save_base
    updated = self._save_table(
              ^^^^^^^^^^^^^^^^^
  File "/Users/pimenvibritania/Moladin/cost-management-system/.venv/lib/python3.11/site-packages/django/db/models/base.py", line 1020, in _save_table
    results = self._do_insert(
              ^^^^^^^^^^^^^^^^
  File "/Users/pimenvibritania/Moladin/cost-management-system/.venv/lib/python3.11/site-packages/django/db/models/base.py", line 1061, in _do_insert
    return manager._insert(
           ^^^^^^^^^^^^^^^^
  File "/Users/pimenvibritania/Moladin/cost-management-system/.venv/lib/python3.11/site-packages/django/db/models/manager.py", line 87, in manager_method
    return getattr(self.get_queryset(), name)(*args, **kwargs)
           ^^^^^^^^^^^^^^^^^^^^^^^^^^^^^^^^^^^^^^^^^^^^^^^^^^^
  File "/Users/pimenvibritania/Moladin/cost-management-system/.venv/lib/python3.11/site-packages/django/db/models/query.py", line 1805, in _insert
    return query.get_compiler(using=using).execute_sql(returning_fields)
           ^^^^^^^^^^^^^^^^^^^^^^^^^^^^^^^^^^^^^^^^^^^^^^^^^^^^^^^^^^^^^
  File "/Users/pimenvibritania/Moladin/cost-management-system/.venv/lib/python3.11/site-packages/django/db/models/sql/compiler.py", line 1822, in execute_sql
    cursor.execute(sql, params)
  File "/Users/pimenvibritania/Moladin/cost-management-system/.venv/lib/python3.11/site-packages/django/db/backends/utils.py", line 102, in execute
    return super().execute(sql, params)
           ^^^^^^^^^^^^^^^^^^^^^^^^^^^^
  File "/Users/pimenvibritania/Moladin/cost-management-system/.venv/lib/python3.11/site-packages/django/db/backends/utils.py", line 67, in execute
    return self._execute_with_wrappers(
           ^^^^^^^^^^^^^^^^^^^^^^^^^^^^
  File "/Users/pimenvibritania/Moladin/cost-management-system/.venv/lib/python3.11/site-packages/django/db/backends/utils.py", line 80, in _execute_with_wrappers
    return executor(sql, params, many, context)
           ^^^^^^^^^^^^^^^^^^^^^^^^^^^^^^^^^^^^
  File "/Users/pimenvibritania/Moladin/cost-management-system/.venv/lib/python3.11/site-packages/django/db/backends/utils.py", line 84, in _execute
    with self.db.wrap_database_errors:
  File "/Users/pimenvibritania/Moladin/cost-management-system/.venv/lib/python3.11/site-packages/django/db/utils.py", line 91, in __exit__
    raise dj_exc_value.with_traceback(traceback) from exc_value
  File "/Users/pimenvibritania/Moladin/cost-management-system/.venv/lib/python3.11/site-packages/django/db/backends/utils.py", line 89, in _execute
    return self.cursor.execute(sql, params)
           ^^^^^^^^^^^^^^^^^^^^^^^^^^^^^^^^
  File "/Users/pimenvibritania/Moladin/cost-management-system/.venv/lib/python3.11/site-packages/django/db/backends/mysql/base.py", line 75, in execute
    return self.cursor.execute(query, args)
           ^^^^^^^^^^^^^^^^^^^^^^^^^^^^^^^^
  File "/Users/pimenvibritania/Moladin/cost-management-system/.venv/lib/python3.11/site-packages/MySQLdb/cursors.py", line 179, in execute
    res = self._query(mogrified_query)
          ^^^^^^^^^^^^^^^^^^^^^^^^^^^^
  File "/Users/pimenvibritania/Moladin/cost-management-system/.venv/lib/python3.11/site-packages/MySQLdb/cursors.py", line 330, in _query
    db.query(q)
  File "/Users/pimenvibritania/Moladin/cost-management-system/.venv/lib/python3.11/site-packages/MySQLdb/connections.py", line 261, in query
    _mysql.connection.query(self, query)
django.db.utils.IntegrityError: (1062, "Duplicate entry '2024-01-31-2062-016F-44A2_//compute.googleapis.com/projects/8379' for key 'gcp_cost_resources.unique_cost_resource_daily_usage'")

During handling of the above exception, another exception occurred:

Traceback (most recent call last):
  File "/Users/pimenvibritania/Moladin/cost-management-system/manage.py", line 22, in <module>
    main()
  File "/Users/pimenvibritania/Moladin/cost-management-system/manage.py", line 18, in main
    execute_from_command_line(sys.argv)
  File "/Users/pimenvibritania/Moladin/cost-management-system/.venv/lib/python3.11/site-packages/django/core/management/__init__.py", line 442, in execute_from_command_line
    utility.execute()
  File "/Users/pimenvibritania/Moladin/cost-management-system/.venv/lib/python3.11/site-packages/django/core/management/__init__.py", line 436, in execute
    self.fetch_command(subcommand).run_from_argv(self.argv)
  File "/Users/pimenvibritania/Moladin/cost-management-system/.venv/lib/python3.11/site-packages/django/core/management/base.py", line 412, in run_from_argv
    self.execute(*args, **cmd_options)
  File "/Users/pimenvibritania/Moladin/cost-management-system/.venv/lib/python3.11/site-packages/django/core/management/base.py", line 458, in execute
    output = self.handle(*args, **options)
             ^^^^^^^^^^^^^^^^^^^^^^^^^^^^^
  File "/Users/pimenvibritania/Moladin/cost-management-system/core/management/commands/sync_gcp_cost_resource.py", line 25, in handle
    GCPCostResource.sync_cost(current_date_f)
  File "/Users/pimenvibritania/Moladin/cost-management-system/api/models/v2/gcp_cost_resource.py", line 234, in sync_cost
    Notification.send_slack_failed(payload)
  File "/Users/pimenvibritania/Moladin/cost-management-system/api/utils/v2/notify.py", line 62, in send_slack_failed
    res_slack = requests.post(
                ^^^^^^^^^^^^^^
  File "/Users/pimenvibritania/Moladin/cost-management-system/.venv/lib/python3.11/site-packages/requests/api.py", line 115, in post
    return request("post", url, data=data, json=json, **kwargs)
           ^^^^^^^^^^^^^^^^^^^^^^^^^^^^^^^^^^^^^^^^^^^^^^^^^^^^
  File "/Users/pimenvibritania/Moladin/cost-management-system/.venv/lib/python3.11/site-packages/requests/api.py", line 59, in request
    return session.request(method=method, url=url, **kwargs)
           ^^^^^^^^^^^^^^^^^^^^^^^^^^^^^^^^^^^^^^^^^^^^^^^^^
  File "/Users/pimenvibritania/Moladin/cost-management-system/.venv/lib/python3.11/site-packages/requests/sessions.py", line 589, in request
    resp = self.send(prep, **send_kwargs)
           ^^^^^^^^^^^^^^^^^^^^^^^^^^^^^^
  File "/Users/pimenvibritania/Moladin/cost-management-system/.venv/lib/python3.11/site-packages/requests/sessions.py", line 703, in send
    r = adapter.send(request, **kwargs)
        ^^^^^^^^^^^^^^^^^^^^^^^^^^^^^^^
  File "/Users/pimenvibritania/Moladin/cost-management-system/.venv/lib/python3.11/site-packages/requests/adapters.py", line 486, in send
    resp = conn.urlopen(
           ^^^^^^^^^^^^^
  File "/Users/pimenvibritania/Moladin/cost-management-system/.venv/lib/python3.11/site-packages/urllib3/connectionpool.py", line 793, in urlopen
    response = self._make_request(
               ^^^^^^^^^^^^^^^^^^^
  File "/Users/pimenvibritania/Moladin/cost-management-system/.venv/lib/python3.11/site-packages/urllib3/connectionpool.py", line 467, in _make_request
    self._validate_conn(conn)
  File "/Users/pimenvibritania/Moladin/cost-management-system/.venv/lib/python3.11/site-packages/urllib3/connectionpool.py", line 1099, in _validate_conn
    conn.connect()
  File "/Users/pimenvibritania/Moladin/cost-management-system/.venv/lib/python3.11/site-packages/urllib3/connection.py", line 653, in connect
    sock_and_verified = _ssl_wrap_socket_and_match_hostname(
                        ^^^^^^^^^^^^^^^^^^^^^^^^^^^^^^^^^^^^
  File "/Users/pimenvibritania/Moladin/cost-management-system/.venv/lib/python3.11/site-packages/urllib3/connection.py", line 806, in _ssl_wrap_socket_and_match_hostname
    ssl_sock = ssl_wrap_socket(
               ^^^^^^^^^^^^^^^^
  File "/Users/pimenvibritania/Moladin/cost-management-system/.venv/lib/python3.11/site-packages/urllib3/util/ssl_.py", line 465, in ssl_wrap_socket
    ssl_sock = _ssl_wrap_socket_impl(sock, context, tls_in_tls, server_hostname)
               ^^^^^^^^^^^^^^^^^^^^^^^^^^^^^^^^^^^^^^^^^^^^^^^^^^^^^^^^^^^^^^^^^
  File "/Users/pimenvibritania/Moladin/cost-management-system/.venv/lib/python3.11/site-packages/urllib3/util/ssl_.py", line 509, in _ssl_wrap_socket_impl
    return ssl_context.wrap_socket(sock, server_hostname=server_hostname)
           ^^^^^^^^^^^^^^^^^^^^^^^^^^^^^^^^^^^^^^^^^^^^^^^^^^^^^^^^^^^^^^
  File "/Library/Frameworks/Python.framework/Versions/3.11/lib/python3.11/ssl.py", line 517, in wrap_socket
    return self.sslsocket_class._create(
           ^^^^^^^^^^^^^^^^^^^^^^^^^^^^^
  File "/Library/Frameworks/Python.framework/Versions/3.11/lib/python3.11/ssl.py", line 1108, in _create
    self.do_handshake()
  File "/Library/Frameworks/Python.framework/Versions/3.11/lib/python3.11/ssl.py", line 1379, in do_handshake
    self._sslobj.do_handshake()
KeyboardInterrupt

2024-07-23 02:49:42,298 - ERROR - Error executing python3 manage.py sync_gcp_cost_resource 2024-02-10 10: Command 'python3 manage.py sync_gcp_cost_resource 2024-02-10 10' died with <Signals.SIGINT: 2>.
Traceback (most recent call last):
  File "/Users/pimenvibritania/Moladin/cost-management-system/.venv/lib/python3.11/site-packages/django/db/backends/utils.py", line 89, in _execute
    return self.cursor.execute(sql, params)
           ^^^^^^^^^^^^^^^^^^^^^^^^^^^^^^^^
  File "/Users/pimenvibritania/Moladin/cost-management-system/.venv/lib/python3.11/site-packages/django/db/backends/mysql/base.py", line 75, in execute
    return self.cursor.execute(query, args)
           ^^^^^^^^^^^^^^^^^^^^^^^^^^^^^^^^
  File "/Users/pimenvibritania/Moladin/cost-management-system/.venv/lib/python3.11/site-packages/MySQLdb/cursors.py", line 179, in execute
    res = self._query(mogrified_query)
          ^^^^^^^^^^^^^^^^^^^^^^^^^^^^
  File "/Users/pimenvibritania/Moladin/cost-management-system/.venv/lib/python3.11/site-packages/MySQLdb/cursors.py", line 330, in _query
    db.query(q)
  File "/Users/pimenvibritania/Moladin/cost-management-system/.venv/lib/python3.11/site-packages/MySQLdb/connections.py", line 261, in query
    _mysql.connection.query(self, query)
MySQLdb.IntegrityError: (1062, "Duplicate entry '2024-02-10-9662-B51E-5089_//sqladmin.googleapis.com/projects/mol' for key 'gcp_cost_resources.unique_cost_resource_daily_usage'")

The above exception was the direct cause of the following exception:

Traceback (most recent call last):
  File "/Users/pimenvibritania/Moladin/cost-management-system/api/models/v2/gcp_cost_resource.py", line 226, in sync_cost
    serializer_cost.save()
  File "/Users/pimenvibritania/Moladin/cost-management-system/.venv/lib/python3.11/site-packages/rest_framework/serializers.py", line 212, in save
    self.instance = self.create(validated_data)
                    ^^^^^^^^^^^^^^^^^^^^^^^^^^^
  File "/Users/pimenvibritania/Moladin/cost-management-system/.venv/lib/python3.11/site-packages/rest_framework/serializers.py", line 962, in create
    instance = ModelClass._default_manager.create(**validated_data)
               ^^^^^^^^^^^^^^^^^^^^^^^^^^^^^^^^^^^^^^^^^^^^^^^^^^^^
  File "/Users/pimenvibritania/Moladin/cost-management-system/.venv/lib/python3.11/site-packages/django/db/models/manager.py", line 87, in manager_method
    return getattr(self.get_queryset(), name)(*args, **kwargs)
           ^^^^^^^^^^^^^^^^^^^^^^^^^^^^^^^^^^^^^^^^^^^^^^^^^^^
  File "/Users/pimenvibritania/Moladin/cost-management-system/.venv/lib/python3.11/site-packages/django/db/models/query.py", line 658, in create
    obj.save(force_insert=True, using=self.db)
  File "/Users/pimenvibritania/Moladin/cost-management-system/.venv/lib/python3.11/site-packages/django/db/models/base.py", line 814, in save
    self.save_base(
  File "/Users/pimenvibritania/Moladin/cost-management-system/.venv/lib/python3.11/site-packages/django/db/models/base.py", line 877, in save_base
    updated = self._save_table(
              ^^^^^^^^^^^^^^^^^
  File "/Users/pimenvibritania/Moladin/cost-management-system/.venv/lib/python3.11/site-packages/django/db/models/base.py", line 1020, in _save_table
    results = self._do_insert(
              ^^^^^^^^^^^^^^^^
  File "/Users/pimenvibritania/Moladin/cost-management-system/.venv/lib/python3.11/site-packages/django/db/models/base.py", line 1061, in _do_insert
    return manager._insert(
           ^^^^^^^^^^^^^^^^
  File "/Users/pimenvibritania/Moladin/cost-management-system/.venv/lib/python3.11/site-packages/django/db/models/manager.py", line 87, in manager_method
    return getattr(self.get_queryset(), name)(*args, **kwargs)
           ^^^^^^^^^^^^^^^^^^^^^^^^^^^^^^^^^^^^^^^^^^^^^^^^^^^
  File "/Users/pimenvibritania/Moladin/cost-management-system/.venv/lib/python3.11/site-packages/django/db/models/query.py", line 1805, in _insert
    return query.get_compiler(using=using).execute_sql(returning_fields)
           ^^^^^^^^^^^^^^^^^^^^^^^^^^^^^^^^^^^^^^^^^^^^^^^^^^^^^^^^^^^^^
  File "/Users/pimenvibritania/Moladin/cost-management-system/.venv/lib/python3.11/site-packages/django/db/models/sql/compiler.py", line 1822, in execute_sql
    cursor.execute(sql, params)
  File "/Users/pimenvibritania/Moladin/cost-management-system/.venv/lib/python3.11/site-packages/django/db/backends/utils.py", line 102, in execute
    return super().execute(sql, params)
           ^^^^^^^^^^^^^^^^^^^^^^^^^^^^
  File "/Users/pimenvibritania/Moladin/cost-management-system/.venv/lib/python3.11/site-packages/django/db/backends/utils.py", line 67, in execute
    return self._execute_with_wrappers(
           ^^^^^^^^^^^^^^^^^^^^^^^^^^^^
  File "/Users/pimenvibritania/Moladin/cost-management-system/.venv/lib/python3.11/site-packages/django/db/backends/utils.py", line 80, in _execute_with_wrappers
    return executor(sql, params, many, context)
           ^^^^^^^^^^^^^^^^^^^^^^^^^^^^^^^^^^^^
  File "/Users/pimenvibritania/Moladin/cost-management-system/.venv/lib/python3.11/site-packages/django/db/backends/utils.py", line 84, in _execute
    with self.db.wrap_database_errors:
  File "/Users/pimenvibritania/Moladin/cost-management-system/.venv/lib/python3.11/site-packages/django/db/utils.py", line 91, in __exit__
    raise dj_exc_value.with_traceback(traceback) from exc_value
  File "/Users/pimenvibritania/Moladin/cost-management-system/.venv/lib/python3.11/site-packages/django/db/backends/utils.py", line 89, in _execute
    return self.cursor.execute(sql, params)
           ^^^^^^^^^^^^^^^^^^^^^^^^^^^^^^^^
  File "/Users/pimenvibritania/Moladin/cost-management-system/.venv/lib/python3.11/site-packages/django/db/backends/mysql/base.py", line 75, in execute
    return self.cursor.execute(query, args)
           ^^^^^^^^^^^^^^^^^^^^^^^^^^^^^^^^
  File "/Users/pimenvibritania/Moladin/cost-management-system/.venv/lib/python3.11/site-packages/MySQLdb/cursors.py", line 179, in execute
    res = self._query(mogrified_query)
          ^^^^^^^^^^^^^^^^^^^^^^^^^^^^
  File "/Users/pimenvibritania/Moladin/cost-management-system/.venv/lib/python3.11/site-packages/MySQLdb/cursors.py", line 330, in _query
    db.query(q)
  File "/Users/pimenvibritania/Moladin/cost-management-system/.venv/lib/python3.11/site-packages/MySQLdb/connections.py", line 261, in query
    _mysql.connection.query(self, query)
django.db.utils.IntegrityError: (1062, "Duplicate entry '2024-02-10-9662-B51E-5089_//sqladmin.googleapis.com/projects/mol' for key 'gcp_cost_resources.unique_cost_resource_daily_usage'")

During handling of the above exception, another exception occurred:

Traceback (most recent call last):
  File "/Users/pimenvibritania/Moladin/cost-management-system/manage.py", line 22, in <module>
    main()
  File "/Users/pimenvibritania/Moladin/cost-management-system/manage.py", line 18, in main
    execute_from_command_line(sys.argv)
  File "/Users/pimenvibritania/Moladin/cost-management-system/.venv/lib/python3.11/site-packages/django/core/management/__init__.py", line 442, in execute_from_command_line
    utility.execute()
  File "/Users/pimenvibritania/Moladin/cost-management-system/.venv/lib/python3.11/site-packages/django/core/management/__init__.py", line 436, in execute
    self.fetch_command(subcommand).run_from_argv(self.argv)
  File "/Users/pimenvibritania/Moladin/cost-management-system/.venv/lib/python3.11/site-packages/django/core/management/base.py", line 412, in run_from_argv
    self.execute(*args, **cmd_options)
  File "/Users/pimenvibritania/Moladin/cost-management-system/.venv/lib/python3.11/site-packages/django/core/management/base.py", line 458, in execute
    output = self.handle(*args, **options)
             ^^^^^^^^^^^^^^^^^^^^^^^^^^^^^
  File "/Users/pimenvibritania/Moladin/cost-management-system/core/management/commands/sync_gcp_cost_resource.py", line 25, in handle
    GCPCostResource.sync_cost(current_date_f)
  File "/Users/pimenvibritania/Moladin/cost-management-system/api/models/v2/gcp_cost_resource.py", line 234, in sync_cost
    Notification.send_slack_failed(payload)
  File "/Users/pimenvibritania/Moladin/cost-management-system/api/utils/v2/notify.py", line 62, in send_slack_failed
    res_slack = requests.post(
                ^^^^^^^^^^^^^^
  File "/Users/pimenvibritania/Moladin/cost-management-system/.venv/lib/python3.11/site-packages/requests/api.py", line 115, in post
    return request("post", url, data=data, json=json, **kwargs)
           ^^^^^^^^^^^^^^^^^^^^^^^^^^^^^^^^^^^^^^^^^^^^^^^^^^^^
  File "/Users/pimenvibritania/Moladin/cost-management-system/.venv/lib/python3.11/site-packages/requests/api.py", line 59, in request
    return session.request(method=method, url=url, **kwargs)
           ^^^^^^^^^^^^^^^^^^^^^^^^^^^^^^^^^^^^^^^^^^^^^^^^^
  File "/Users/pimenvibritania/Moladin/cost-management-system/.venv/lib/python3.11/site-packages/requests/sessions.py", line 589, in request
    resp = self.send(prep, **send_kwargs)
           ^^^^^^^^^^^^^^^^^^^^^^^^^^^^^^
  File "/Users/pimenvibritania/Moladin/cost-management-system/.venv/lib/python3.11/site-packages/requests/sessions.py", line 703, in send
    r = adapter.send(request, **kwargs)
        ^^^^^^^^^^^^^^^^^^^^^^^^^^^^^^^
  File "/Users/pimenvibritania/Moladin/cost-management-system/.venv/lib/python3.11/site-packages/requests/adapters.py", line 486, in send
    resp = conn.urlopen(
           ^^^^^^^^^^^^^
  File "/Users/pimenvibritania/Moladin/cost-management-system/.venv/lib/python3.11/site-packages/urllib3/connectionpool.py", line 793, in urlopen
    response = self._make_request(
               ^^^^^^^^^^^^^^^^^^^
  File "/Users/pimenvibritania/Moladin/cost-management-system/.venv/lib/python3.11/site-packages/urllib3/connectionpool.py", line 537, in _make_request
    response = conn.getresponse()
               ^^^^^^^^^^^^^^^^^^
  File "/Users/pimenvibritania/Moladin/cost-management-system/.venv/lib/python3.11/site-packages/urllib3/connection.py", line 466, in getresponse
    httplib_response = super().getresponse()
                       ^^^^^^^^^^^^^^^^^^^^^
  File "/Library/Frameworks/Python.framework/Versions/3.11/lib/python3.11/http/client.py", line 1378, in getresponse
    response.begin()
  File "/Library/Frameworks/Python.framework/Versions/3.11/lib/python3.11/http/client.py", line 318, in begin
    version, status, reason = self._read_status()
                              ^^^^^^^^^^^^^^^^^^^
  File "/Library/Frameworks/Python.framework/Versions/3.11/lib/python3.11/http/client.py", line 279, in _read_status
    line = str(self.fp.readline(_MAXLINE + 1), "iso-8859-1")
               ^^^^^^^^^^^^^^^^^^^^^^^^^^^^^^
  File "/Library/Frameworks/Python.framework/Versions/3.11/lib/python3.11/socket.py", line 706, in readinto
    return self._sock.recv_into(b)
           ^^^^^^^^^^^^^^^^^^^^^^^
  File "/Library/Frameworks/Python.framework/Versions/3.11/lib/python3.11/ssl.py", line 1311, in recv_into
    return self.read(nbytes, buffer)
           ^^^^^^^^^^^^^^^^^^^^^^^^^
  File "/Library/Frameworks/Python.framework/Versions/3.11/lib/python3.11/ssl.py", line 1167, in read
    return self._sslobj.read(len, buffer)
           ^^^^^^^^^^^^^^^^^^^^^^^^^^^^^^
KeyboardInterrupt

2024-07-23 02:49:42,311 - ERROR - Error executing python3 manage.py sync_gcp_cost_resource 2024-01-21 10: Command 'python3 manage.py sync_gcp_cost_resource 2024-01-21 10' died with <Signals.SIGINT: 2>.
Traceback (most recent call last):
  File "/Users/pimenvibritania/Moladin/cost-management-system/manage.py", line 22, in <module>
    main()
  File "/Users/pimenvibritania/Moladin/cost-management-system/manage.py", line 18, in main
    execute_from_command_line(sys.argv)
  File "/Users/pimenvibritania/Moladin/cost-management-system/.venv/lib/python3.11/site-packages/django/core/management/__init__.py", line 442, in execute_from_command_line
    utility.execute()
  File "/Users/pimenvibritania/Moladin/cost-management-system/.venv/lib/python3.11/site-packages/django/core/management/__init__.py", line 436, in execute
    self.fetch_command(subcommand).run_from_argv(self.argv)
  File "/Users/pimenvibritania/Moladin/cost-management-system/.venv/lib/python3.11/site-packages/django/core/management/base.py", line 412, in run_from_argv
    self.execute(*args, **cmd_options)
  File "/Users/pimenvibritania/Moladin/cost-management-system/.venv/lib/python3.11/site-packages/django/core/management/base.py", line 458, in execute
    output = self.handle(*args, **options)
             ^^^^^^^^^^^^^^^^^^^^^^^^^^^^^
  File "/Users/pimenvibritania/Moladin/cost-management-system/core/management/commands/sync_gcp_cost_resource.py", line 25, in handle
    GCPCostResource.sync_cost(current_date_f)
  File "/Users/pimenvibritania/Moladin/cost-management-system/api/models/v2/gcp_cost_resource.py", line 201, in sync_cost
    "conversion_rate": BQ.get_daily_conversion_rate(usage_date),
                       ^^^^^^^^^^^^^^^^^^^^^^^^^^^^^^^^^^^^^^^^
  File "/Users/pimenvibritania/Moladin/cost-management-system/api/models/bigquery.py", line 62, in get_daily_conversion_rate
    for res in query_job.result():
               ^^^^^^^^^^^^^^^^^^
  File "/Users/pimenvibritania/Moladin/cost-management-system/.venv/lib/python3.11/site-packages/google/cloud/bigquery/job/query.py", line 1590, in result
    do_get_result()
  File "/Users/pimenvibritania/Moladin/cost-management-system/.venv/lib/python3.11/site-packages/google/api_core/retry/retry_unary.py", line 293, in retry_wrapped_func
    return retry_target(
           ^^^^^^^^^^^^^
  File "/Users/pimenvibritania/Moladin/cost-management-system/.venv/lib/python3.11/site-packages/google/api_core/retry/retry_unary.py", line 144, in retry_target
    result = target()
             ^^^^^^^^
  File "/Users/pimenvibritania/Moladin/cost-management-system/.venv/lib/python3.11/site-packages/google/cloud/bigquery/job/query.py", line 1585, in do_get_result
    self._reload_query_results(retry=retry, timeout=timeout)
  File "/Users/pimenvibritania/Moladin/cost-management-system/.venv/lib/python3.11/site-packages/google/cloud/bigquery/job/query.py", line 1424, in _reload_query_results
    self._query_results = self._client._get_query_results(
                          ^^^^^^^^^^^^^^^^^^^^^^^^^^^^^^^^
  File "/Users/pimenvibritania/Moladin/cost-management-system/.venv/lib/python3.11/site-packages/google/cloud/bigquery/client.py", line 2015, in _get_query_results
    resource = self._call_api(
               ^^^^^^^^^^^^^^^
  File "/Users/pimenvibritania/Moladin/cost-management-system/.venv/lib/python3.11/site-packages/google/cloud/bigquery/client.py", line 831, in _call_api
    return call()
           ^^^^^^
  File "/Users/pimenvibritania/Moladin/cost-management-system/.venv/lib/python3.11/site-packages/google/api_core/retry/retry_unary.py", line 293, in retry_wrapped_func
    return retry_target(
           ^^^^^^^^^^^^^
  File "/Users/pimenvibritania/Moladin/cost-management-system/.venv/lib/python3.11/site-packages/google/api_core/retry/retry_unary.py", line 144, in retry_target
    result = target()
             ^^^^^^^^
  File "/Users/pimenvibritania/Moladin/cost-management-system/.venv/lib/python3.11/site-packages/google/cloud/_http/__init__.py", line 482, in api_request
    response = self._make_request(
               ^^^^^^^^^^^^^^^^^^^
  File "/Users/pimenvibritania/Moladin/cost-management-system/.venv/lib/python3.11/site-packages/google/cloud/_http/__init__.py", line 341, in _make_request
    return self._do_request(
           ^^^^^^^^^^^^^^^^^
  File "/Users/pimenvibritania/Moladin/cost-management-system/.venv/lib/python3.11/site-packages/google/cloud/_http/__init__.py", line 379, in _do_request
    return self.http.request(
           ^^^^^^^^^^^^^^^^^^
  File "/Users/pimenvibritania/Moladin/cost-management-system/.venv/lib/python3.11/site-packages/google/auth/transport/requests.py", line 541, in request
    response = super(AuthorizedSession, self).request(
               ^^^^^^^^^^^^^^^^^^^^^^^^^^^^^^^^^^^^^^^
  File "/Users/pimenvibritania/Moladin/cost-management-system/.venv/lib/python3.11/site-packages/requests/sessions.py", line 589, in request
    resp = self.send(prep, **send_kwargs)
           ^^^^^^^^^^^^^^^^^^^^^^^^^^^^^^
  File "/Users/pimenvibritania/Moladin/cost-management-system/.venv/lib/python3.11/site-packages/requests/sessions.py", line 703, in send
    r = adapter.send(request, **kwargs)
        ^^^^^^^^^^^^^^^^^^^^^^^^^^^^^^^
  File "/Users/pimenvibritania/Moladin/cost-management-system/.venv/lib/python3.11/site-packages/requests/adapters.py", line 486, in send
    resp = conn.urlopen(
           ^^^^^^^^^^^^^
  File "/Users/pimenvibritania/Moladin/cost-management-system/.venv/lib/python3.11/site-packages/urllib3/connectionpool.py", line 793, in urlopen
    response = self._make_request(
               ^^^^^^^^^^^^^^^^^^^
  File "/Users/pimenvibritania/Moladin/cost-management-system/.venv/lib/python3.11/site-packages/urllib3/connectionpool.py", line 537, in _make_request
    response = conn.getresponse()
               ^^^^^^^^^^^^^^^^^^
  File "/Users/pimenvibritania/Moladin/cost-management-system/.venv/lib/python3.11/site-packages/urllib3/connection.py", line 466, in getresponse
    httplib_response = super().getresponse()
                       ^^^^^^^^^^^^^^^^^^^^^
  File "/Library/Frameworks/Python.framework/Versions/3.11/lib/python3.11/http/client.py", line 1378, in getresponse
    response.begin()
  File "/Library/Frameworks/Python.framework/Versions/3.11/lib/python3.11/http/client.py", line 318, in begin
    version, status, reason = self._read_status()
                              ^^^^^^^^^^^^^^^^^^^
  File "/Library/Frameworks/Python.framework/Versions/3.11/lib/python3.11/http/client.py", line 279, in _read_status
    line = str(self.fp.readline(_MAXLINE + 1), "iso-8859-1")
               ^^^^^^^^^^^^^^^^^^^^^^^^^^^^^^
  File "/Library/Frameworks/Python.framework/Versions/3.11/lib/python3.11/socket.py", line 706, in readinto
    return self._sock.recv_into(b)
           ^^^^^^^^^^^^^^^^^^^^^^^
  File "/Library/Frameworks/Python.framework/Versions/3.11/lib/python3.11/ssl.py", line 1311, in recv_into
    return self.read(nbytes, buffer)
           ^^^^^^^^^^^^^^^^^^^^^^^^^
  File "/Library/Frameworks/Python.framework/Versions/3.11/lib/python3.11/ssl.py", line 1167, in read
    return self._sslobj.read(len, buffer)
           ^^^^^^^^^^^^^^^^^^^^^^^^^^^^^^
KeyboardInterrupt

